Traceback (most recent call last):
  File "C:\Users\Martin\anaconda3\envs\py37\lib\site-packages\nbclient\client.py", line 622, in _async_poll_for_reply
    msg = await ensure_async(self.kc.shell_channel.get_msg(timeout=new_timeout))
  File "C:\Users\Martin\anaconda3\envs\py37\lib\site-packages\nbclient\util.py", line 85, in ensure_async
    result = await obj
  File "C:\Users\Martin\anaconda3\envs\py37\lib\site-packages\jupyter_client\channels.py", line 230, in get_msg
    raise Empty
_queue.Empty

During handling of the above exception, another exception occurred:

Traceback (most recent call last):
  File "C:\Users\Martin\anaconda3\envs\py37\lib\site-packages\jupyter_cache\executors\utils.py", line 56, in single_nb_execution
    record_timing=False,
  File "C:\Users\Martin\anaconda3\envs\py37\lib\site-packages\nbclient\client.py", line 1112, in execute
    return NotebookClient(nb=nb, resources=resources, km=km, **kwargs).execute()
  File "C:\Users\Martin\anaconda3\envs\py37\lib\site-packages\nbclient\util.py", line 74, in wrapped
    return just_run(coro(*args, **kwargs))
  File "C:\Users\Martin\anaconda3\envs\py37\lib\site-packages\nbclient\util.py", line 53, in just_run
    return loop.run_until_complete(coro)
  File "C:\Users\Martin\anaconda3\envs\py37\lib\asyncio\base_events.py", line 587, in run_until_complete
    return future.result()
  File "C:\Users\Martin\anaconda3\envs\py37\lib\site-packages\nbclient\client.py", line 554, in async_execute
    cell, index, execution_count=self.code_cells_executed + 1
  File "C:\Users\Martin\anaconda3\envs\py37\lib\site-packages\nbclient\client.py", line 841, in async_execute_cell
    exec_reply = await self.task_poll_for_reply
  File "C:\Users\Martin\anaconda3\envs\py37\lib\site-packages\nbclient\client.py", line 646, in _async_poll_for_reply
    await self._async_handle_timeout(timeout, cell)
  File "C:\Users\Martin\anaconda3\envs\py37\lib\site-packages\nbclient\client.py", line 697, in _async_handle_timeout
    "Cell execution timed out", timeout, cell
nbclient.exceptions.CellTimeoutError: A cell timed out while it was being executed, after 30 seconds.
The message was: Cell execution timed out.
Here is a preview of the cell contents:
-------------------
['model = Sequential()', '', 'model.add(Conv2D(16, kernel_size=(3, 3), activation="relu", input_shape=(28,28,1,)))', "model.add(Conv2D(32,(3,3),activation = 'relu'))", 'model.add(MaxPooling2D(pool_size=(2,2)))']
...
['model.fit(', '    X_train,', '    y_train,', '    epochs=15,', '    batch_size=100)']
-------------------

