Traceback (most recent call last):
  File "C:\Users\Martin\anaconda3\envs\py37\lib\site-packages\jupyter_cache\executors\utils.py", line 56, in single_nb_execution
    record_timing=False,
  File "C:\Users\Martin\anaconda3\envs\py37\lib\site-packages\nbclient\client.py", line 1112, in execute
    return NotebookClient(nb=nb, resources=resources, km=km, **kwargs).execute()
  File "C:\Users\Martin\anaconda3\envs\py37\lib\site-packages\nbclient\util.py", line 74, in wrapped
    return just_run(coro(*args, **kwargs))
  File "C:\Users\Martin\anaconda3\envs\py37\lib\site-packages\nbclient\util.py", line 53, in just_run
    return loop.run_until_complete(coro)
  File "C:\Users\Martin\anaconda3\envs\py37\lib\asyncio\base_events.py", line 587, in run_until_complete
    return future.result()
  File "C:\Users\Martin\anaconda3\envs\py37\lib\site-packages\nbclient\client.py", line 554, in async_execute
    cell, index, execution_count=self.code_cells_executed + 1
  File "C:\Users\Martin\anaconda3\envs\py37\lib\site-packages\nbclient\client.py", line 857, in async_execute_cell
    self._check_raise_for_error(cell, exec_reply)
  File "C:\Users\Martin\anaconda3\envs\py37\lib\site-packages\nbclient\client.py", line 760, in _check_raise_for_error
    raise CellExecutionError.from_cell_and_msg(cell, exec_reply_content)
nbclient.exceptions.CellExecutionError: An error occurred while executing the following cell:
------------------
nrow = 5
ncol = 5



#fig = plt.figure(figsize=(ncol+1, nrow+1)) 
fig = plt.figure(figsize=(24, 24))

gs = gridspec.GridSpec(nrow, ncol,
         wspace=0.0, hspace=0.0, 
         top=1.-0.5/(nrow+1), bottom=0.5/(nrow+1), 
         left=0.5/(ncol+1), right=1-0.5/(ncol+1))

im = 0
for i in range(nrow):
    for j in range(ncol):
        # convert to unsigned integers
        
        ax= plt.subplot(gs[i,j])
        ax.imshow(X_train[im,:,:,0].astype('uint8'),cmap='gray')
        ax.set_xticklabels([])
        ax.set_yticklabels([])
        im +=1

plt.show()
------------------

[1;31m---------------------------------------------------------------------------[0m
[1;31mNameError[0m                                 Traceback (most recent call last)
[1;32m~\AppData\Local\Temp/ipykernel_10716/2437109.py[0m in [0;36m<module>[1;34m[0m
[0;32m     18[0m [1;33m[0m[0m
[0;32m     19[0m         [0max[0m[1;33m=[0m [0mplt[0m[1;33m.[0m[0msubplot[0m[1;33m([0m[0mgs[0m[1;33m[[0m[0mi[0m[1;33m,[0m[0mj[0m[1;33m][0m[1;33m)[0m[1;33m[0m[1;33m[0m[0m
[1;32m---> 20[1;33m         [0max[0m[1;33m.[0m[0mimshow[0m[1;33m([0m[0mX_train[0m[1;33m[[0m[0mim[0m[1;33m,[0m[1;33m:[0m[1;33m,[0m[1;33m:[0m[1;33m,[0m[1;36m0[0m[1;33m][0m[1;33m.[0m[0mastype[0m[1;33m([0m[1;34m'uint8'[0m[1;33m)[0m[1;33m,[0m[0mcmap[0m[1;33m=[0m[1;34m'gray'[0m[1;33m)[0m[1;33m[0m[1;33m[0m[0m
[0m[0;32m     21[0m         [0max[0m[1;33m.[0m[0mset_xticklabels[0m[1;33m([0m[1;33m[[0m[1;33m][0m[1;33m)[0m[1;33m[0m[1;33m[0m[0m
[0;32m     22[0m         [0max[0m[1;33m.[0m[0mset_yticklabels[0m[1;33m([0m[1;33m[[0m[1;33m][0m[1;33m)[0m[1;33m[0m[1;33m[0m[0m

[1;31mNameError[0m: name 'X_train' is not defined
NameError: name 'X_train' is not defined

